Workbook

Sheet Setup
A1: Portfolio Simulator — Test Spreadsheet
A3: Monthly Investment | B3: 2000
A4: Investment Years | B4: 5
A5: Tax Rate | B5: 0.25
A6: Total Months | B6: 61
A8: Ticker | B8: Name | C8: Allocation %
A9: XLK | B9: Information Technology | C9: 0.3
A10: XLV | B10: Health Care | C10: 0.2
A11: XLF | B11: Financials | C11: 0.2
A12: XLE | B12: Energy | C12: 0.15
A13: XLP | B13: Consumer Staples | C13: 0.15
A16: Month | B16: MM Rate | C16: XLK High | D16: XLK Close | E16: XLK Div/Share | F16: XLV High | G16: XLV Close | H16: XLV Div/Share | I16: XLF High | J16: XLF Close | K16: XLF Div/Share | L16: XLE High | M16: XLE Close | N16: XLE Div/Share | O16: XLP High | P16: XLP Close | Q16: XLP Div/Share
A17: Feb 2021 | B17: 0.0008 | C17: 69.620003 | D17: 65.345001 | E17: 0 | F17: 117.54 | G17: 112.61 | H17: 0 | I17: 33.84 | J17: 32.310001 | K17: 0 | L17: 25.405001 | M17: 24.075001 | N17: 0 | O17: 66.410004 | P17: 63.299999 | Q17: 0
A18: Mar 2021 | B18: 0.0007 | C18: 67.589996 | D18: 66.404999 | E18: 0.1365 | F18: 117.97 | G18: 116.74 | H18: 0.398 | I18: 35.290001 | J18: 34.049999 | K18: 0.151 | L18: 27.184999 | M18: 24.530001 | N18: 0.26 | O18: 69.330002 | P18: 68.309998 | Q18: 0.357
A19: Apr 2021 | B19: 0.0007 | C19: 71.885002 | D19: 69.849998 | E19: 0 | F19: 123.96 | G19: 121.33 | H19: 0 | I19: 36.610001 | J19: 36.259998 | K19: 0 | L19: 25.645 | M19: 24.695 | N19: 0 | O19: 70.470001 | P19: 69.580002 | Q19: 0
A20: May 2021 | B20: 0.0006 | C20: 70.364998 | D20: 69.199997 | E20: 0 | F20: 125.66 | G20: 123.6 | H20: 0 | I20: 38.259998 | J20: 37.990002 | K20: 0 | L20: 27.57 | M20: 26.105 | N20: 0 | O20: 71.639999 | P20: 70.809998 | Q20: 0
A21: Jun 2021 | B21: 0.0008 | C21: 74.010002 | D21: 73.830002 | E21: 0.13 | F21: 126.42 | G21: 125.95 | H21: 0.481 | I21: 38.599998 | J21: 36.689999 | K21: 0.139 | L21: 28.325001 | M21: 26.934999 | N21: 0.265 | O21: 71.690002 | P21: 69.970001 | Q21: 0.444
A22: Jul 2021 | B22: 0.001 | C22: 77.360001 | D22: 76.699997 | E22: 0 | F22: 132.64 | G22: 132.14999 | H22: 0 | I22: 37.139999 | J22: 36.52 | K22: 0 | L22: 27.635 | M22: 24.695 | N22: 0 | O22: 71.980003 | P22: 71.510002 | Q22: 0
A23: Aug 2021 | B23: 0.0009 | C23: 79.945 | D23: 79.43 | E23: 0 | F23: 136.98 | G23: 135.21001 | H23: 0 | I23: 39.040001 | J23: 38.400002 | K23: 0 | L23: 25.309999 | M23: 24.200001 | N23: 0 | O23: 73.25 | P23: 72.260002 | Q23: 0
A24: Sep 2021 | B24: 0.0008 | C24: 80.065002 | D24: 74.660004 | E24: 0.1365 | F24: 137.03999 | G24: 127.3 | H24: 0.467 | I24: 38.919998 | J24: 37.529999 | K24: 0.162 | L24: 26.915001 | M24: 26.045 | N24: 0.296 | O24: 73.040001 | P24: 68.839996 | Q24: 0.442
A25: Oct 2021 | B25: 0.0008 | C25: 80.815002 | D25: 80.764999 | E25: 0 | F25: 133.99001 | G25: 133.82001 | H25: 0 | I25: 40.860001 | J25: 40.259998 | K25: 0 | L25: 29.705 | M25: 28.735001 | N25: 0 | O25: 71.910004 | P25: 71.25 | Q25: 0
A26: Nov 2021 | B26: 0.0008 | C26: 87.125 | D26: 84.360001 | E26: 0 | F26: 135.34 | G26: 129.73 | H26: 0 | I26: 40.68 | J26: 37.959999 | K26: 0 | L26: 29.700001 | M26: 27.295 | N26: 0 | O26: 73.379997 | P26: 70.290001 | Q26: 0
A27: Dec 2021 | B27: 0.0008 | C27: 88.519997 | D27: 86.934998 | E27: 0.1585 | F27: 141.98 | G27: 140.89 | H27: 0.528 | I27: 39.740002 | J27: 39.049999 | K27: 0.184 | L27: 28.934999 | M27: 27.75 | N27: 0.3475 | O27: 77.230003 | P27: 77.110001 | Q27: 0.512
A28: Jan 2022 | B28: 0.0008 | C28: 88 | D28: 80.985001 | E28: 0 | F28: 140.55 | G28: 131.23 | H28: 0 | I28: 41.700001 | J28: 39.060001 | K28: 0 | L28: 33.529999 | M28: 32.959999 | N28: 0 | O28: 78.18 | P28: 75.970001 | Q28: 0
... A77: Feb 2026 | B77: 0 | C77: 146.14999 | D77: 141.13 | E77: 0 | F77: 157.8 | G77: 157.71001 | H77: 0 | I77: 54.349998 | J77: 54.259998 | K77: 0 | L77: 53.419998 | M77: 53.25 | N77: 0 | O77: 88.089996 | P77: 87.940002 | Q77: 0

Sheet Monthly Sim
A1: Month | B1: MM Rate | C1: Prior Div Bal | D1: MM Interest | E1: Div Bal After Int | F1: XLK Invested | G1: XLK Shares | H1: XLK Cum Shares | I1: XLK Divs | J1: XLK Value | K1: XLV Invested | L1: XLV Shares | M1: XLV Cum Shares | N1: XLV Divs | O1: XLV Value | P1: XLF Invested | Q1: XLF Shares | R1: XLF Cum Shares | S1: XLF Divs | T1: XLF Value | U1: XLE Invested | V1: XLE Shares | W1: XLE Cum Shares | X1: XLE Divs | Y1: XLE Value | Z1: XLP Invested | AA1: XLP Shares | AB1: XLP Cum Shares | AC1: XLP Divs | AD1: XLP Value | AE1: Monthly Divs | AF1: Div Bal End | AG1: Cum Invested | AH1: Portfolio Value | AI1: MM-Only Bal
A2: =Setup!A17 | B2: =Setup!B17 | C2: 0 | D2: =ROUND(C2*B2/12,2) | E2: =C2+D2 | F2: =Setup!$B$3*Setup!$C$9 | G2: =IF(Setup!C17>0,F2/Setup!C17,0) | H2: =G2 | I2: =H2*Setup!E17 | J2: =H2*Setup!D17 | K2: =Setup!$B$3*Setup!$C$10 | L2: =IF(Setup!F17>0,K2/Setup!F17,0) | M2: =L2 | N2: =M2*Setup!H17 | O2: =M2*Setup!G17 | P2: =Setup!$B$3*Setup!$C$11 | Q2: =IF(Setup!I17>0,P2/Setup!I17,0) | R2: =Q2 | S2: =R2*Setup!K17 | T2: =R2*Setup!J17 | U2: =Setup!$B$3*Setup!$C$12 | V2: =IF(Setup!L17>0,U2/Setup!L17,0) | W2: =V2 | X2: =W2*Setup!N17 | Y2: =W2*Setup!M17 | Z2: =Setup!$B$3*Setup!$C$13 | AA2: =IF(Setup!O17>0,Z2/Setup!O17,0) | AB2: =AA2 | AC2: =AB2*Setup!Q17 | AD2: =AB2*Setup!P17 | AE2: =I2+N2+S2+X2+AC2 | AF2: =E2+AE2 | AG2: =F2+K2+P2+U2+Z2 | AH2: =J2+O2+T2+Y2+AD2 | AI2: =ROUND(0*(1+B2/12),2)+Setup!$B$3
A3: =Setup!A18 | B3: =Setup!B18 | C3: =AF2 | D3: =ROUND(C3*B3/12,2) | E3: =C3+D3 | F3: =Setup!$B$3*Setup!$C$9 | G3: =IF(Setup!C18>0,F3/Setup!C18,0) | H3: =H2+G3 | I3: =H3*Setup!E18 | J3: =H3*Setup!D18 | K3: =Setup!$B$3*Setup!$C$10 | L3: =IF(Setup!F18>0,K3/Setup!F18,0) | M3: =M2+L3 | N3: =M3*Setup!H18 | O3: =M3*Setup!G18 | P3: =Setup!$B$3*Setup!$C$11 | Q3: =IF(Setup!I18>0,P3/Setup!I18,0) | R3: =R2+Q3 | S3: =R3*Setup!K18 | T3: =R3*Setup!J18 | U3: =Setup!$B$3*Setup!$C$12 | V3: =IF(Setup!L18>0,U3/Setup!L18,0) | W3: =W2+V3 | X3: =W3*Setup!N18 | Y3: =W3*Setup!M18 | Z3: =Setup!$B$3*Setup!$C$13 | AA3: =IF(Setup!O18>0,Z3/Setup!O18,0) | AB3: =AB2+AA3 | AC3: =AB3*Setup!Q18 | AD3: =AB3*Setup!P18 | AE3: =I3+N3+S3+X3+AC3 | AF3: =E3+AE3 | AG3: =AG2+F3+K3+P3+U3+Z3 | AH3: =J3+O3+T3+Y3+AD3 | AI3: =ROUND(AI2*(1+B3/12),2)+Setup!$B$3
A4: =Setup!A19 | B4: =Setup!B19 | C4: =AF3 | D4: =ROUND(C4*B4/12,2) | E4: =C4+D4 | F4: =Setup!$B$3*Setup!$C$9 | G4: =IF(Setup!C19>0,F4/Setup!C19,0) | H4: =H3+G4 | I4: =H4*Setup!E19 | J4: =H4*Setup!D19 | K4: =Setup!$B$3*Setup!$C$10 | L4: =IF(Setup!F19>0,K4/Setup!F19,0) | M4: =M3+L4 | N4: =M4*Setup!H19 | O4: =M4*Setup!G19 | P4: =Setup!$B$3*Setup!$C$11 | Q4: =IF(Setup!I19>0,P4/Setup!I19,0) | R4: =R3+Q4 | S4: =R4*Setup!K19 | T4: =R4*Setup!J19 | U4: =Setup!$B$3*Setup!$C$12 | V4: =IF(Setup!L19>0,U4/Setup!L19,0) | W4: =W3+V4 | X4: =W4*Setup!N19 | Y4: =W4*Setup!M19 | Z4: =Setup!$B$3*Setup!$C$13 | AA4: =IF(Setup!O19>0,Z4/Setup!O19,0) | AB4: =AB3+AA4 | AC4: =AB4*Setup!Q19 | AD4: =AB4*Setup!P19 | AE4: =I4+N4+S4+X4+AC4 | AF4: =E4+AE4 | AG4: =AG3+F4+K4+P4+U4+Z4 | AH4: =J4+O4+T4+Y4+AD4 | AI4: =ROUND(AI3*(1+B4/12),2)+Setup!$B$3
A5: =Setup!A20 | B5: =Setup!B20 | C5: =AF4 | D5: =ROUND(C5*B5/12,2) | E5: =C5+D5 | F5: =Setup!$B$3*Setup!$C$9 | G5: =IF(Setup!C20>0,F5/Setup!C20,0) | H5: =H4+G5 | I5: =H5*Setup!E20 | J5: =H5*Setup!D20 | K5: =Setup!$B$3*Setup!$C$10 | L5: =IF(Setup!F20>0,K5/Setup!F20,0) | M5: =M4+L5 | N5: =M5*Setup!H20 | O5: =M5*Setup!G20 | P5: =Setup!$B$3*Setup!$C$11 | Q5: =IF(Setup!I20>0,P5/Setup!I20,0) | R5: =R4+Q5 | S5: =R5*Setup!K20 | T5: =R5*Setup!J20 | U5: =Setup!$B$3*Setup!$C$12 | V5: =IF(Setup!L20>0,U5/Setup!L20,0) | W5: =W4+V5 | X5: =W5*Setup!N20 | Y5: =W5*Setup!M20 | Z5: =Setup!$B$3*Setup!$C$13 | AA5: =IF(Setup!O20>0,Z5/Setup!O20,0) | AB5: =AB4+AA5 | AC5: =AB5*Setup!Q20 | AD5: =AB5*Setup!P20 | AE5: =I5+N5+S5+X5+AC5 | AF5: =E5+AE5 | AG5: =AG4+F5+K5+P5+U5+Z5 | AH5: =J5+O5+T5+Y5+AD5 | AI5: =ROUND(AI4*(1+B5/12),2)+Setup!$B$3
A6: =Setup!A21 | B6: =Setup!B21 | C6: =AF5 | D6: =ROUND(C6*B6/12,2) | E6: =C6+D6 | F6: =Setup!$B$3*Setup!$C$9 | G6: =IF(Setup!C21>0,F6/Setup!C21,0) | H6: =H5+G6 | I6: =H6*Setup!E21 | J6: =H6*Setup!D21 | K6: =Setup!$B$3*Setup!$C$10 | L6: =IF(Setup!F21>0,K6/Setup!F21,0) | M6: =M5+L6 | N6: =M6*Setup!H21 | O6: =M6*Setup!G21 | P6: =Setup!$B$3*Setup!$C$11 | Q6: =IF(Setup!I21>0,P6/Setup!I21,0) | R6: =R5+Q6 | S6: =R6*Setup!K21 | T6: =R6*Setup!J21 | U6: =Setup!$B$3*Setup!$C$12 | V6: =IF(Setup!L21>0,U6/Setup!L21,0) | W6: =W5+V6 | X6: =W6*Setup!N21 | Y6: =W6*Setup!M21 | Z6: =Setup!$B$3*Setup!$C$13 | AA6: =IF(Setup!O21>0,Z6/Setup!O21,0) | AB6: =AB5+AA6 | AC6: =AB6*Setup!Q21 | AD6: =AB6*Setup!P21 | AE6: =I6+N6+S6+X6+AC6 | AF6: =E6+AE6 | AG6: =AG5+F6+K6+P6+U6+Z6 | AH6: =J6+O6+T6+Y6+AD6 | AI6: =ROUND(AI5*(1+B6/12),2)+Setup!$B$3
A7: =Setup!A22 | B7: =Setup!B22 | C7: =AF6 | D7: =ROUND(C7*B7/12,2) | E7: =C7+D7 | F7: =Setup!$B$3*Setup!$C$9 | G7: =IF(Setup!C22>0,F7/Setup!C22,0) | H7: =H6+G7 | I7: =H7*Setup!E22 | J7: =H7*Setup!D22 | K7: =Setup!$B$3*Setup!$C$10 | L7: =IF(Setup!F22>0,K7/Setup!F22,0) | M7: =M6+L7 | N7: =M7*Setup!H22 | O7: =M7*Setup!G22 | P7: =Setup!$B$3*Setup!$C$11 | Q7: =IF(Setup!I22>0,P7/Setup!I22,0) | R7: =R6+Q7 | S7: =R7*Setup!K22 | T7: =R7*Setup!J22 | U7: =Setup!$B$3*Setup!$C$12 | V7: =IF(Setup!L22>0,U7/Setup!L22,0) | W7: =W6+V7 | X7: =W7*Setup!N22 | Y7: =W7*Setup!M22 | Z7: =Setup!$B$3*Setup!$C$13 | AA7: =IF(Setup!O22>0,Z7/Setup!O22,0) | AB7: =AB6+AA7 | AC7: =AB7*Setup!Q22 | AD7: =AB7*Setup!P22 | AE7: =I7+N7+S7+X7+AC7 | AF7: =E7+AE7 | AG7: =AG6+F7+K7+P7+U7+Z7 | AH7: =J7+O7+T7+Y7+AD7 | AI7: =ROUND(AI6*(1+B7/12),2)+Setup!$B$3
A8: =Setup!A23 | B8: =Setup!B23 | C8: =AF7 | D8: =ROUND(C8*B8/12,2) | E8: =C8+D8 | F8: =Setup!$B$3*Setup!$C$9 | G8: =IF(Setup!C23>0,F8/Setup!C23,0) | H8: =H7+G8 | I8: =H8*Setup!E23 | J8: =H8*Setup!D23 | K8: =Setup!$B$3*Setup!$C$10 | L8: =IF(Setup!F23>0,K8/Setup!F23,0) | M8: =M7+L8 | N8: =M8*Setup!H23 | O8: =M8*Setup!G23 | P8: =Setup!$B$3*Setup!$C$11 | Q8: =IF(Setup!I23>0,P8/Setup!I23,0) | R8: =R7+Q8 | S8: =R8*Setup!K23 | T8: =R8*Setup!J23 | U8: =Setup!$B$3*Setup!$C$12 | V8: =IF(Setup!L23>0,U8/Setup!L23,0) | W8: =W7+V8 | X8: =W8*Setup!N23 | Y8: =W8*Setup!M23 | Z8: =Setup!$B$3*Setup!$C$13 | AA8: =IF(Setup!O23>0,Z8/Setup!O23,0) | AB8: =AB7+AA8 | AC8: =AB8*Setup!Q23 | AD8: =AB8*Setup!P23 | AE8: =I8+N8+S8+X8+AC8 | AF8: =E8+AE8 | AG8: =AG7+F8+K8+P8+U8+Z8 | AH8: =J8+O8+T8+Y8+AD8 | AI8: =ROUND(AI7*(1+B8/12),2)+Setup!$B$3
A9: =Setup!A24 | B9: =Setup!B24 | C9: =AF8 | D9: =ROUND(C9*B9/12,2) | E9: =C9+D9 | F9: =Setup!$B$3*Setup!$C$9 | G9: =IF(Setup!C24>0,F9/Setup!C24,0) | H9: =H8+G9 | I9: =H9*Setup!E24 | J9: =H9*Setup!D24 | K9: =Setup!$B$3*Setup!$C$10 | L9: =IF(Setup!F24>0,K9/Setup!F24,0) | M9: =M8+L9 | N9: =M9*Setup!H24 | O9: =M9*Setup!G24 | P9: =Setup!$B$3*Setup!$C$11 | Q9: =IF(Setup!I24>0,P9/Setup!I24,0) | R9: =R8+Q9 | S9: =R9*Setup!K24 | T9: =R9*Setup!J24 | U9: =Setup!$B$3*Setup!$C$12 | V9: =IF(Setup!L24>0,U9/Setup!L24,0) | W9: =W8+V9 | X9: =W9*Setup!N24 | Y9: =W9*Setup!M24 | Z9: =Setup!$B$3*Setup!$C$13 | AA9: =IF(Setup!O24>0,Z9/Setup!O24,0) | AB9: =AB8+AA9 | AC9: =AB9*Setup!Q24 | AD9: =AB9*Setup!P24 | AE9: =I9+N9+S9+X9+AC9 | AF9: =E9+AE9 | AG9: =AG8+F9+K9+P9+U9+Z9 | AH9: =J9+O9+T9+Y9+AD9 | AI9: =ROUND(AI8*(1+B9/12),2)+Setup!$B$3
A10: =Setup!A25 | B10: =Setup!B25 | C10: =AF9 | D10: =ROUND(C10*B10/12,2) | E10: =C10+D10 | F10: =Setup!$B$3*Setup!$C$9 | G10: =IF(Setup!C25>0,F10/Setup!C25,0) | H10: =H9+G10 | I10: =H10*Setup!E25 | J10: =H10*Setup!D25 | K10: =Setup!$B$3*Setup!$C$10 | L10: =IF(Setup!F25>0,K10/Setup!F25,0) | M10: =M9+L10 | N10: =M10*Setup!H25 | O10: =M10*Setup!G25 | P10: =Setup!$B$3*Setup!$C$11 | Q10: =IF(Setup!I25>0,P10/Setup!I25,0) | R10: =R9+Q10 | S10: =R10*Setup!K25 | T10: =R10*Setup!J25 | U10: =Setup!$B$3*Setup!$C$12 | V10: =IF(Setup!L25>0,U10/Setup!L25,0) | W10: =W9+V10 | X10: =W10*Setup!N25 | Y10: =W10*Setup!M25 | Z10: =Setup!$B$3*Setup!$C$13 | AA10: =IF(Setup!O25>0,Z10/Setup!O25,0) | AB10: =AB9+AA10 | AC10: =AB10*Setup!Q25 | AD10: =AB10*Setup!P25 | AE10: =I10+N10+S10+X10+AC10 | AF10: =E10+AE10 | AG10: =AG9+F10+K10+P10+U10+Z10 | AH10: =J10+O10+T10+Y10+AD10 | AI10: =ROUND(AI9*(1+B10/12),2)+Setup!$B$3
A11: =Setup!A26 | B11: =Setup!B26 | C11: =AF10 | D11: =ROUND(C11*B11/12,2) | E11: =C11+D11 | F11: =Setup!$B$3*Setup!$C$9 | G11: =IF(Setup!C26>0,F11/Setup!C26,0) | H11: =H10+G11 | I11: =H11*Setup!E26 | J11: =H11*Setup!D26 | K11: =Setup!$B$3*Setup!$C$10 | L11: =IF(Setup!F26>0,K11/Setup!F26,0) | M11: =M10+L11 | N11: =M11*Setup!H26 | O11: =M11*Setup!G26 | P11: =Setup!$B$3*Setup!$C$11 | Q11: =IF(Setup!I26>0,P11/Setup!I26,0) | R11: =R10+Q11 | S11: =R11*Setup!K26 | T11: =R11*Setup!J26 | U11: =Setup!$B$3*Setup!$C$12 | V11: =IF(Setup!L26>0,U11/Setup!L26,0) | W11: =W10+V11 | X11: =W11*Setup!N26 | Y11: =W11*Setup!M26 | Z11: =Setup!$B$3*Setup!$C$13 | AA11: =IF(Setup!O26>0,Z11/Setup!O26,0) | AB11: =AB10+AA11 | AC11: =AB11*Setup!Q26 | AD11: =AB11*Setup!P26 | AE11: =I11+N11+S11+X11+AC11 | AF11: =E11+AE11 | AG11: =AG10+F11+K11+P11+U11+Z11 | AH11: =J11+O11+T11+Y11+AD11 | AI11: =ROUND(AI10*(1+B11/12),2)+Setup!$B$3
A12: =Setup!A27 | B12: =Setup!B27 | C12: =AF11 | D12: =ROUND(C12*B12/12,2) | E12: =C12+D12 | F12: =Setup!$B$3*Setup!$C$9 | G12: =IF(Setup!C27>0,F12/Setup!C27,0) | H12: =H11+G12 | I12: =H12*Setup!E27 | J12: =H12*Setup!D27 | K12: =Setup!$B$3*Setup!$C$10 | L12: =IF(Setup!F27>0,K12/Setup!F27,0) | M12: =M11+L12 | N12: =M12*Setup!H27 | O12: =M12*Setup!G27 | P12: =Setup!$B$3*Setup!$C$11 | Q12: =IF(Setup!I27>0,P12/Setup!I27,0) | R12: =R11+Q12 | S12: =R12*Setup!K27 | T12: =R12*Setup!J27 | U12: =Setup!$B$3*Setup!$C$12 | V12: =IF(Setup!L27>0,U12/Setup!L27,0) | W12: =W11+V12 | X12: =W12*Setup!N27 | Y12: =W12*Setup!M27 | Z12: =Setup!$B$3*Setup!$C$13 | AA12: =IF(Setup!O27>0,Z12/Setup!O27,0) | AB12: =AB11+AA12 | AC12: =AB12*Setup!Q27 | AD12: =AB12*Setup!P27 | AE12: =I12+N12+S12+X12+AC12 | AF12: =E12+AE12 | AG12: =AG11+F12+K12+P12+U12+Z12 | AH12: =J12+O12+T12+Y12+AD12 | AI12: =ROUND(AI11*(1+B12/12),2)+Setup!$B$3
A13: =Setup!A28 | B13: =Setup!B28 | C13: =AF12 | D13: =ROUND(C13*B13/12,2) | E13: =C13+D13 | F13: =Setup!$B$3*Setup!$C$9 | G13: =IF(Setup!C28>0,F13/Setup!C28,0) | H13: =H12+G13 | I13: =H13*Setup!E28 | J13: =H13*Setup!D28 | K13: =Setup!$B$3*Setup!$C$10 | L13: =IF(Setup!F28>0,K13/Setup!F28,0) | M13: =M12+L13 | N13: =M13*Setup!H28 | O13: =M13*Setup!G28 | P13: =Setup!$B$3*Setup!$C$11 | Q13: =IF(Setup!I28>0,P13/Setup!I28,0) | R13: =R12+Q13 | S13: =R13*Setup!K28 | T13: =R13*Setup!J28 | U13: =Setup!$B$3*Setup!$C$12 | V13: =IF(Setup!L28>0,U13/Setup!L28,0) | W13: =W12+V13 | X13: =W13*Setup!N28 | Y13: =W13*Setup!M28 | Z13: =Setup!$B$3*Setup!$C$13 | AA13: =IF(Setup!O28>0,Z13/Setup!O28,0) | AB13: =AB12+AA13 | AC13: =AB13*Setup!Q28 | AD13: =AB13*Setup!P28 | AE13: =I13+N13+S13+X13+AC13 | AF13: =E13+AE13 | AG13: =AG12+F13+K13+P13+U13+Z13 | AH13: =J13+O13+T13+Y13+AD13 | AI13: =ROUND(AI12*(1+B13/12),2)+Setup!$B$3
A14: =Setup!A29 | B14: =Setup!B29 | C14: =AF13 | D14: =ROUND(C14*B14/12,2) | E14: =C14+D14 | F14: =Setup!$B$3*Setup!$C$9 | G14: =IF(Setup!C29>0,F14/Setup!C29,0) | H14: =H13+G14 | I14: =H14*Setup!E29 | J14: =H14*Setup!D29 | K14: =Setup!$B$3*Setup!$C$10 | L14: =IF(Setup!F29>0,K14/Setup!F29,0) | M14: =M13+L14 | N14: =M14*Setup!H29 | O14: =M14*Setup!G29 | P14: =Setup!$B$3*Setup!$C$11 | Q14: =IF(Setup!I29>0,P14/Setup!I29,0) | R14: =R13+Q14 | S14: =R14*Setup!K29 | T14: =R14*Setup!J29 | U14: =Setup!$B$3*Setup!$C$12 | V14: =IF(Setup!L29>0,U14/Setup!L29,0) | W14: =W13+V14 | X14: =W14*Setup!N29 | Y14: =W14*Setup!M29 | Z14: =Setup!$B$3*Setup!$C$13 | AA14: =IF(Setup!O29>0,Z14/Setup!O29,0) | AB14: =AB13+AA14 | AC14: =AB14*Setup!Q29 | AD14: =AB14*Setup!P29 | AE14: =I14+N14+S14+X14+AC14 | AF14: =E14+AE14 | AG14: =AG13+F14+K14+P14+U14+Z14 | AH14: =J14+O14+T14+Y14+AD14 | AI14: =ROUND(AI13*(1+B14/12),2)+Setup!$B$3
... A62: =Setup!A77 | B62: =Setup!B77 | C62: =AF61 | D62: =ROUND(C62*B62/12,2) | E62: =C62+D62 | F62: =Setup!$B$3*Setup!$C$9 | G62: =IF(Setup!C77>0,F62/Setup!C77,0) | H62: =H61+G62 | I62: =H62*Setup!E77 | J62: =H62*Setup!D77 | K62: =Setup!$B$3*Setup!$C$10 | L62: =IF(Setup!F77>0,K62/Setup!F77,0) | M62: =M61+L62 | N62: =M62*Setup!H77 | O62: =M62*Setup!G77 | P62: =Setup!$B$3*Setup!$C$11 | Q62: =IF(Setup!I77>0,P62/Setup!I77,0) | R62: =R61+Q62 | S62: =R62*Setup!K77 | T62: =R62*Setup!J77 | U62: =Setup!$B$3*Setup!$C$12 | V62: =IF(Setup!L77>0,U62/Setup!L77,0) | W62: =W61+V62 | X62: =W62*Setup!N77 | Y62: =W62*Setup!M77 | Z62: =Setup!$B$3*Setup!$C$13 | AA62: =IF(Setup!O77>0,Z62/Setup!O77,0) | AB62: =AB61+AA62 | AC62: =AB62*Setup!Q77 | AD62: =AB62*Setup!P77 | AE62: =I62+N62+S62+X62+AC62 | AF62: =E62+AE62 | AG62: =AG61+F62+K62+P62+U62+Z62 | AH62: =J62+O62+T62+Y62+AD62 | AI62: =ROUND(AI61*(1+B62/12),2)+Setup!$B$3

Sheet Year Summary
A1: Year | B1: Invested | C1: Cum Invested | D1: Dividends | E1: MM Interest | F1: End Stock Value | G1: End Div Bal
A2: 2021 | B2: =SUM('Monthly Sim'!F2:F12)+SUM('Monthly Sim'!K2:K12)+SUM('Monthly Sim'!P2:P12)+SUM('Monthly Sim'!U2:U12)+SUM('Monthly Sim'!Z2:Z12) | C2: ='Monthly Sim'!AG12 | D2: =SUM('Monthly Sim'!AE2:AE12) | E2: =SUM('Monthly Sim'!D2:D12) | F2: ='Monthly Sim'!AH12 | G2: ='Monthly Sim'!AF12
A3: 2022 | B3: =SUM('Monthly Sim'!F13:F24)+SUM('Monthly Sim'!K13:K24)+SUM('Monthly Sim'!P13:P24)+SUM('Monthly Sim'!U13:U24)+SUM('Monthly Sim'!Z13:Z24) | C3: ='Monthly Sim'!AG24 | D3: =SUM('Monthly Sim'!AE13:AE24) | E3: =SUM('Monthly Sim'!D13:D24) | F3: ='Monthly Sim'!AH24 | G3: ='Monthly Sim'!AF24
A4: 2023 | B4: =SUM('Monthly Sim'!F25:F36)+SUM('Monthly Sim'!K25:K36)+SUM('Monthly Sim'!P25:P36)+SUM('Monthly Sim'!U25:U36)+SUM('Monthly Sim'!Z25:Z36) | C4: ='Monthly Sim'!AG36 | D4: =SUM('Monthly Sim'!AE25:AE36) | E4: =SUM('Monthly Sim'!D25:D36) | F4: ='Monthly Sim'!AH36 | G4: ='Monthly Sim'!AF36
A5: 2024 | B5: =SUM('Monthly Sim'!F37:F48)+SUM('Monthly Sim'!K37:K48)+SUM('Monthly Sim'!P37:P48)+SUM('Monthly Sim'!U37:U48)+SUM('Monthly Sim'!Z37:Z48) | C5: ='Monthly Sim'!AG48 | D5: =SUM('Monthly Sim'!AE37:AE48) | E5: =SUM('Monthly Sim'!D37:D48) | F5: ='Monthly Sim'!AH48 | G5: ='Monthly Sim'!AF48
A6: 2025 | B6: =SUM('Monthly Sim'!F49:F60)+SUM('Monthly Sim'!K49:K60)+SUM('Monthly Sim'!P49:P60)+SUM('Monthly Sim'!U49:U60)+SUM('Monthly Sim'!Z49:Z60) | C6: ='Monthly Sim'!AG60 | D6: =SUM('Monthly Sim'!AE49:AE60) | E6: =SUM('Monthly Sim'!D49:D60) | F6: ='Monthly Sim'!AH60 | G6: ='Monthly Sim'!AF60
A7: 2026 | B7: =SUM('Monthly Sim'!F61:F62)+SUM('Monthly Sim'!K61:K62)+SUM('Monthly Sim'!P61:P62)+SUM('Monthly Sim'!U61:U62)+SUM('Monthly Sim'!Z61:Z62) | C7: ='Monthly Sim'!AG62 | D7: =SUM('Monthly Sim'!AE61:AE62) | E7: =SUM('Monthly Sim'!D61:D62) | F7: ='Monthly Sim'!AH62 | G7: ='Monthly Sim'!AF62

Sheet Tax Impact
A1: Year | B1: Dividends | C1: Tax on Dividends | D1: MM Interest | E1: Tax on Interest | F1: Total Taxes
A2: ='Year Summary'!A2 | B2: ='Year Summary'!D2 | C2: =B2*Setup!$B$5 | D2: ='Year Summary'!E2 | E2: =D2*Setup!$B$5 | F2: =C2+E2
A3: ='Year Summary'!A3 | B3: ='Year Summary'!D3 | C3: =B3*Setup!$B$5 | D3: ='Year Summary'!E3 | E3: =D3*Setup!$B$5 | F3: =C3+E3
A4: ='Year Summary'!A4 | B4: ='Year Summary'!D4 | C4: =B4*Setup!$B$5 | D4: ='Year Summary'!E4 | E4: =D4*Setup!$B$5 | F4: =C4+E4
A5: ='Year Summary'!A5 | B5: ='Year Summary'!D5 | C5: =B5*Setup!$B$5 | D5: ='Year Summary'!E5 | E5: =D5*Setup!$B$5 | F5: =C5+E5
A6: ='Year Summary'!A6 | B6: ='Year Summary'!D6 | C6: =B6*Setup!$B$5 | D6: ='Year Summary'!E6 | E6: =D6*Setup!$B$5 | F6: =C6+E6
A7: ='Year Summary'!A7 | B7: ='Year Summary'!D7 | C7: =B7*Setup!$B$5 | D7: ='Year Summary'!E7 | E7: =D7*Setup!$B$5 | F7: =C7+E7
A8: TOTAL | B8: =SUM(B2:B7) | C8: =SUM(C2:C7) | D8: =SUM(D2:D7) | E8: =SUM(E2:E7) | F8: =SUM(F2:F7)

Sheet Annual Returns
A1: Year | B1: Invested | C1: Dividends | D1: MM Interest | E1: Stock Value | F1: Portfolio Value | G1: After-Tax Value | H1: Pre-Tax Return | I1: After-Tax Return
A2: ='Year Summary'!A2 | B2: ='Year Summary'!B2 | C2: ='Year Summary'!D2 | D2: ='Year Summary'!E2 | E2: ='Year Summary'!F2 | F2: ='Year Summary'!F2+'Year Summary'!G2 | G2: =F2-'Tax Impact'!F2 | H2: =C9 | I2: =C10
B3: Beginning Stock Value | C3: 0
B4: Stock Gain | C4: =E2-C3-B2 | D4: End Stock Value - Beginning - Invested
B5: Avg Invested Capital | C5: =B2*0.542 | D5: Invested x 0.542 (DCA mid-year)
B6: Base Capital (Denominator) | C6: =C3+C5 | D6: Beginning Stock Value + Avg Invested
B7: Total Gain (Numerator) | C7: =C4+C2+D2 | D7: Stock Gain + Dividends + MM Interest
B8: After-Tax Gain | C8: =C4+(C2-'Tax Impact'!C2)+(D2-'Tax Impact'!E2) | D8: Stock Gain + (Divs-Tax) + (MMInt-Tax)
B9: Pre-Tax Return | C9: =IF(C6>0,C7/C6,0) | D9: Total Gain / Base Capital
B10: After-Tax Return | C10: =IF(C6>0,C8/C6,0) | D10: After-Tax Gain / Base Capital
A12: ='Year Summary'!A3 | B12: ='Year Summary'!B3 | C12: ='Year Summary'!D3 | D12: ='Year Summary'!E3 | E12: ='Year Summary'!F3 | F12: ='Year Summary'!F3+'Year Summary'!G3 | G12: =F12-'Tax Impact'!F3 | H12: =C19 | I12: =C20
B13: Beginning Stock Value | C13: ='Year Summary'!F2
B14: Stock Gain | C14: =E12-C13-B12 | D14: End Stock Value - Beginning - Invested
B15: Avg Invested Capital | C15: =B12*0.542 | D15: Invested x 0.542 (DCA mid-year)
B16: Base Capital (Denominator) | C16: =C13+C15 | D16: Beginning Stock Value + Avg Invested
B17: Total Gain (Numerator) | C17: =C14+C12+D12 | D17: Stock Gain + Dividends + MM Interest
B18: After-Tax Gain | C18: =C14+(C12-'Tax Impact'!C3)+(D12-'Tax Impact'!E3) | D18: Stock Gain + (Divs-Tax) + (MMInt-Tax)
B19: Pre-Tax Return | C19: =IF(C16>0,C17/C16,0) | D19: Total Gain / Base Capital
B20: After-Tax Return | C20: =IF(C16>0,C18/C16,0) | D20: After-Tax Gain / Base Capital
A22: ='Year Summary'!A4 | B22: ='Year Summary'!B4 | C22: ='Year Summary'!D4 | D22: ='Year Summary'!E4 | E22: ='Year Summary'!F4 | F22: ='Year Summary'!F4+'Year Summary'!G4 | G22: =F22-'Tax Impact'!F4 | H22: =C29 | I22: =C30
B23: Beginning Stock Value | C23: ='Year Summary'!F3
B24: Stock Gain | C24: =E22-C23-B22 | D24: End Stock Value - Beginning - Invested
B25: Avg Invested Capital | C25: =B22*0.542 | D25: Invested x 0.542 (DCA mid-year)
B26: Base Capital (Denominator) | C26: =C23+C25 | D26: Beginning Stock Value + Avg Invested
B27: Total Gain (Numerator) | C27: =C24+C22+D22 | D27: Stock Gain + Dividends + MM Interest
B28: After-Tax Gain | C28: =C24+(C22-'Tax Impact'!C4)+(D22-'Tax Impact'!E4) | D28: Stock Gain + (Divs-Tax) + (MMInt-Tax)
B29: Pre-Tax Return | C29: =IF(C26>0,C27/C26,0) | D29: Total Gain / Base Capital
B30: After-Tax Return | C30: =IF(C26>0,C28/C26,0) | D30: After-Tax Gain / Base Capital
A32: ='Year Summary'!A5 | B32: ='Year Summary'!B5 | C32: ='Year Summary'!D5 | D32: ='Year Summary'!E5 | E32: ='Year Summary'!F5 | F32: ='Year Summary'!F5+'Year Summary'!G5 | G32: =F32-'Tax Impact'!F5 | H32: =C39 | I32: =C40
B33: Beginning Stock Value | C33: ='Year Summary'!F4
B34: Stock Gain | C34: =E32-C33-B32 | D34: End Stock Value - Beginning - Invested
B35: Avg Invested Capital | C35: =B32*0.542 | D35: Invested x 0.542 (DCA mid-year)
B36: Base Capital (Denominator) | C36: =C33+C35 | D36: Beginning Stock Value + Avg Invested
B37: Total Gain (Numerator) | C37: =C34+C32+D32 | D37: Stock Gain + Dividends + MM Interest
B38: After-Tax Gain | C38: =C34+(C32-'Tax Impact'!C5)+(D32-'Tax Impact'!E5) | D38: Stock Gain + (Divs-Tax) + (MMInt-Tax)
B39: Pre-Tax Return | C39: =IF(C36>0,C37/C36,0) | D39: Total Gain / Base Capital
B40: After-Tax Return | C40: =IF(C36>0,C38/C36,0) | D40: After-Tax Gain / Base Capital
A42: ='Year Summary'!A6 | B42: ='Year Summary'!B6 | C42: ='Year Summary'!D6 | D42: ='Year Summary'!E6 | E42: ='Year Summary'!F6 | F42: ='Year Summary'!F6+'Year Summary'!G6 | G42: =F42-'Tax Impact'!F6 | H42: =C49 | I42: =C50
B43: Beginning Stock Value | C43: ='Year Summary'!F5
B44: Stock Gain | C44: =E42-C43-B42 | D44: End Stock Value - Beginning - Invested
...
